Workbook
Name _Key1: #REF!
Name _Key1: #REF!
Name _Key1: 'Bomba Jockey'!$H$106:$H$108
Name _Key1: 'Cuarto Bombas'!$H$69:$H$71
Name _Key1: #REF!
Name _Key1: #REF!
Name _Key1: #REF!
Name _Key1: 'Sistema 1'!$G$56:$G$57
Name _Key1: 'Sistema 1A'!$G$55:$G$56
Name _Key1: 'Sistema 2 '!$G$56:$G$57
Name _Key1: 'Sistema 2A '!$G$55:$G$56
Name _Key1: 'Sistema 3 '!$G$56:$G$57
Name _Key1: 'Sistema 3A '!$G$55:$G$56
Name _Key1: 'Sistema 4'!$G$58:$G$59
Name _Key1: 'Sistema 5'!$G$56:$G$57
Name _Key1: 'Sistema 6'!$G$56:$G$57
Name _Key1: 'Sistema 9'!$G$56:$G$57
Name _Key1: 'Sistema 9A'!$G$55:$G$56
Name _Key1: #REF!
Name _Key2: 'Bomba Jockey'!$B$104:$B$123
Name _Key2: 'Cuarto Bombas'!$B$67:$B$86
Name _Key2: '[1]RIPMCB'!$C$64:$C$83
Name _Key2: 'Sistema 1'!$B$54:$B$67
Name _Key2: 'Sistema 1A'!$B$53:$B$67
Name _Key2: 'Sistema 2 '!$B$54:$B$68
Name _Key2: 'Sistema 2A '!$B$53:$B$66
Name _Key2: 'Sistema 3 '!$B$54:$B$69
Name _Key2: 'Sistema 3A '!$B$53:$B$67
Name _Key2: 'Sistema 4'!$B$56:$B$72
Name _Key2: 'Sistema 5'!$B$54:$B$68
Name _Key2: 'Sistema 6'!$B$54:$B$68
Name _Key2: 'Sistema 9'!$B$54:$B$68
Name _Key2: 'Sistema 9A'!$B$53:$B$67
Name _Key2: '[2]RIPMCB'!$C$64:$C$83
Name _Order1: 255
Name _Order2: 255
Name _Sort: #REF!
Name _Sort: #REF!
Name _Sort: 'Bomba Jockey'!$B$104:$H$108
Name _Sort: 'Cuarto Bombas'!$B$67:$H$71
Name _Sort: #REF!
Name _Sort: #REF!
Name _Sort: #REF!
Name _Sort: 'Sistema 1'!$B$54:$G$57
Name _Sort: 'Sistema 1A'!$B$53:$G$56
Name _Sort: 'Sistema 2 '!$B$54:$G$57
Name _Sort: 'Sistema 2A '!$B$53:$G$56
Name _Sort: 'Sistema 3 '!$B$54:$G$57
Name _Sort: 'Sistema 3A '!$B$53:$G$56
Name _Sort: 'Sistema 4'!$B$56:$G$59
Name _Sort: 'Sistema 5'!$B$54:$G$57
Name _Sort: 'Sistema 6'!$B$54:$G$57
Name _Sort: 'Sistema 9'!$B$54:$G$57
Name _Sort: 'Sistema 9A'!$B$53:$G$56
Name _Sort: #REF!
Name Print_Titles_MI: 'Bomba Jockey'!$1:$15
Name Print_Titles_MI: 'Cuarto Bombas'!$1:$15
Name Print_Titles_MI: ''FM200'!FM200'!$1:$14
Name Print_Titles_MI: 'Hidrantes Interiores'!$1:$14
Name Print_Titles_MI: 'Hidrantes Interiores (2)'!$1:$14

Sheet Tanque Agua
Q1: FIRE CONTROL SYSTEMS
Q2: Bucarest 12 Terranova Nogales, Sonora
Q3: Tel. 104-1127 Cel. 631-357-9141 las 24 Hrs.
Q4: Patricia Campos Badillo
Q5: RFC. CABP721117CW7
Q6: firecontrolsystems@hotmail.com
B7: REPORTE DE INSPECCIÓN, PRUEBAS Y MANTENIMIENTO A TANQUE DE ABASTECIMIENTO DE AGUA
B8: CLIENTE: | C8: Master Lock de Nogales Planta 2 | K8: CONTRATO : | M8: Mensual
B9: ATENCIÓN: | C9: Ing. Julio Landabazo | K9: INSPECTOR : | M9: Santiago Campos
B10: SERVICIO: | C10: 7 de 12 | K10: FECHA : | M10: 16 de Julio del 2025
C12: Tanque de Agua
B14: f = FRECUENCIA M = MENSUAL Q = TRIMESTRAL A = ANUAL | H14: S: SATISFACTORIO N/A: NO APLICA N: NO SATISFACTORIO
B16: ABASTECIMIENTO DE AGUA | H16: f | I16: S | J16: N/A | K16: N | L16: PARAMETROS | M16: LECTURAS | P16: COMENTARIOS
B17: ¿ La condición del agua es aceptable ? | H17: M | I17: OK
B18: ¿ La válvula de suministro se encuentra abierta ? | H18: M | I18: OK
B19: ¿ La válvula de altitud opera adecuadamente ? | H19: M | I19: OK
B20: ¿ La válvula de flotador opera adecuadamente ? | H20: M | I20: OK
B21: ¿ El nivel de agua en el tanque es el adecuado ? | H21: M | I21: OK | L21: FT | M21: 29.6
B22: ¿ Las paredes del Tanque están en buenas condiciones físicas ? | H22: M | I22: OK
B23: ¿ La entrada hombre esta en buenas condiciones ? | H23: M | I23: OK
B24: ¿ Cuenta con indicaciones de "área restringida" ? | H24: M | I24: OK
B25: ¿ Las válvulas cuentan con señalizaciones ? | H25: M | I25: OK
B26: ¿ La línea de retorno se encuentra en buenas condiciones ? | H26: M | I26: OK
B27: ¿ La condición física del exterior del tanque es satisfactoria ? | H27: M | I27: OK
B28: ¿ El soporte estructural del tanque esta en buen estado ? | H28: M | I28: OK
B29: ¿ Las escalera y pasos de gato no presentan daño físico ? | H29: M | I29: OK
B30: ¿ El área exterior del tanque esta libre de materiales que presenten riesgo de fuego ? | H30: M | I30: OK
B31: ¿ El área exterior del tanque esta libre de materiales que aceleren la corrosión ? | H31: M | I31: OK
B32: ¿ Se verifico el tubo de venteo del tanque ? | H32: M | I32: OK
B33: ¿ Se probo la alarma de alto y bajo nivel ? | H33: M | I33: OK
B34: ¿ Se le dio mantenimiento a las válvulas de control ? | H34: A | I34: OK | P34: 45809
B36: OBSERVACIONES:
B37: El acceso a la escalera no se encuentra restringido.
G42: ELABORO :
G43: =M9 -> Santiago Campos
G45: =M10 -> 16 de Julio del 2025
G46: NOMBRE, FIRMA Y FECHA

Sheet Cuarto Bombas
Q1: FIRE CONTROL SYSTEMS
Q2: Bucarest 12 Terranova Nogales, Sonora
Q3: Tel. 104-1127 Cel. 631-357-9141 las 24 Hrs.
Q4: Patricia Campos Badillo
Q5: RFC. CABP721117CW7
B6: REPORTE DE INSPECCION, PRUEBAS Y MANTENIMIENTO DE CUARTO DE BOMBAS | Q6: firecontrolsystems@hotmail.com
B7: CLIENTE: | C7: Master Lock de Nogales Planta 2 | M7: CONTRATO : | P7: Mensual
B8: ATENCIÓN: | C8: Ing. Julio Landabazos | M8: INSPECTOR : | P8: ='Tanque Agua'!M9 -> Santiago Campos
B9: SERVICIO: | C9: ='Tanque Agua'!C10 -> 7 de 12 | M9: FECHA : | P9: ='Tanque Agua'!M10 -> 16 de Julio del 2025
C11: CUARTO DE BOMBAS
B13: f = FRECUENCIA M = MENSUAL Q = TRIMESTRAL A = ANUAL | H13: S: SATISFACTORIO N/A: NO APLICA N: NO SATISFACTORIO
B15: CUARTO DE BOMBAS CONTRA INCENDIO | H15: f | I15: S | J15: N/A | K15: N | L15: PARAMETROS | M15: LECTURAS | P15: COMENTARIOS
B16: ¿ Se tiene la tarjeta (permiso de puesta fuera de servicio) autorizado por el cliente ? | H16: M | J16: N/A
B17: ¿ Las alarmas de evacuación han sido deshabilitadas ? | H17: M | I17: OK
B18: ¿ Es accesible la entrada ? | H18: M | I18: OK
B19: ¿ Se encuentra limpio y ordenado ? | H19: M | I19: OK
B20: ¿ Se encuentra a la temperatura adecuada ? | H20: M | I20: OK | L20: mínimo 10°C | M20: 23.8° C | P20: No cuenta con termometro
B21: ¿ Esta ventilada el área ? | H21: M | I21: OK | L21: Rejillas | M21: 2
B22: ¿ Cuenta con buena iluminación ? | H22: M | I22: OK | L22: Lámparas | M22: 6
B23: ¿ Cuenta con sistema de rociadores automáticos ? | H23: M | I23: OK | L23: Rociadores | M23: 6
B24: ¿ La válvula de control cierra y retorna a la posición de abierto ? | H24: M | I24: OK
B25: ¿ La válvula de control esta supervisada y/o asegurada ? | H25: M | I25: OK
B26: Número de vueltas para el cierre de la válvula de control. | H26: A | I26: OK | L26: de 6 a 20 | M26: 9.5 | P26: 45809
B27: Presión en la línea de alimentación | H27: M | I27: OK | L27: PSI | M27: 155
B28: ¿ La presión de alimentación es adecuada ? | H28: M | I28: OK
B29: Presión en la línea de rociadores | H29: M | I29: OK | L29: PSI | M29: 160
B30: ¿ La presión del sistema es adecuada ? | H30: M | I30: OK
B31: ¿ Coincide la lectura de los manómetros del riser con el manómetro certificado ? | H31: M | I31: OK
B32: ¿ La válvula de alivio de la línea de inspección opera ? | H32: M | I32: OK
B33: ¿ La valvula se encuentra en condiciones físicas adecuadas ? | H33: M | I33: OK
B34: Tiempo de respuesta del detector de flujo al abrir la válvula de inspección. | H34: Q | I34: OK | L34: de 30 a 60 seg. | N34: 50 | P34: 45809
B35: ¿ Se encuentran las instalaciones adecuadas para la prueba de eficiencia de la bomba ? | H35: M | I35: OK
B37: OBSERVACIONES:
B39: Permanece material de desecho a un lado del tanque de diesel este material puede actuar como combustible ante un conato de incendio.
G44: ELABORO :
G45: =P8 -> Santiago Campos
G47: =P9 -> 16 de Julio del 2025
G48: NOMBRE, FIRMA Y FECHA

Sheet Bomba Jockey
Q1: FIRE CONTROL SYSTEMS
Q2: Bucarest 12 Terranova Nogales, Sonora
Q3: Tel. 104-1127 Cel. 631-357-9141 las 24 Hrs.
Q4: Patricia Campos Bandillo
Q5: RFC. CABP721117CW7
B6: REPORTE DE INSPECCION, PRUEBAS Y MANTENIMIENTO DE BOMBA JOCKEY | Q6: firecontrolsystems@hotmail.com
B7: CLIENTE: | C7: Master Lock de Nogales Planta 2 | J7: CONTRATO : | M7: Mensual
B8: ATENCIÓN: | C8: Ing. Julio Landabazo | J8: INSPECTOR : | M8: Santiago Campos
B9: SERVICIO: | C9: ='Tanque Agua'!C10 -> 7 de 12 | J9: FECHA : | M9: ='Tanque Agua'!M10 -> 16 de Julio del 2025
C11: BOMBA JOCKEY
B13: f = FRECUENCIA M = MENSUAL Q = TRIMESTRAL A = ANUAL | H13: S: SATISFACTORIO N/A: NO APLICA N: NO SATISFACTORIO
B15: BOMBA JOCKEY | H15: f | I15: S | J15: N/A | K15: N | L15: PARAMETROS | M15: LECTURAS | P15: COMENTARIOS
B16: ¿ La válvula de succión esta abierta ? | H16: M | I16: OK
B17: ¿ La válvula de descarga esta abierta ? | H17: M | I17: OK
B18: ¿ La válvula de succión esta asegurada y/o supervisada ? | H18: M | I18: OK
B19: ¿ La válvula de descarga esta asegurada y/o supervisada ? | H19: M | I19: OK
B20: ¿ Las válvulas de succión y descarga son del tipo indicativas ? | H20: M | I20: OK
B21: Número de vueltas para el cierre de la válvula de succión. | H21: A | I21: OK | L21: de 6 a 20 | M21: 9.75 | P21: 45809
B22: Número de vueltas para el cierre de la válvula de descarga. | H22: A | I22: OK | L22: de 6 a 20 | M22: 8.5 | P22: 45809
B23: ¿ Se encontró el selector en automático ? | H23: M | I23: OK
B24: ¿ Opera correctamente el Interruptor principal del tablero de control ? | H24: M | I24: OK
B25: ¿ El tablero y sus componentes siguen aprobados ? | H25: M | I25: OK | L25: FM y/o UL | N25: UL
I26: OK | L26: Volts | M26: L1 - L2: | O26: 490
B27: ¿ Se verifico el voltaje de entrada del interruptor principal ? | H27: M | I27: OK | L27: Volts | M27: L3 - L2: | O27: 490
I28: OK | L28: Volts | M28: L1 - L3: | O28: 487
I29: OK | L29: Volts | M29: V1 - V2: | O29: 490
B30: ¿ Se verifico el voltaje de salida del interruptor principal ? | H30: M | I30: OK | L30: Volts | M30: V3 - V2: | O30: 490
I31: OK | L31: Volts | M31: V1 - V3: | O31: 487
B32: ¿ Se verifico el voltaje de entrada del dispositivo termomagnetico ? | L32: Volts | M32: L1 - L2: | O32: 490
H33: M | L33: Volts | M33: L3 - L2: | O33: 490
L34: Volts | M34: L1 - L3: | O34: 487
B35: ¿ Se verifico el voltaje de salida del dispositivo termomagnetico ? | I35: OK | L35: Volts | M35: V1 - V2: | O35: 490
H36: M | I36: OK | L36: Volts | M36: V3 - V2: | O36: 490
I37: OK | L37: Volts | M37: V1 - V3: | O37: 487
I38: OK | L38: Volts | M38: V1 - V2: | O38: 490
B39: ¿ Se verifico el voltaje de entrada del contactor de arranque ? | H39: M | I39: OK | L39: Volts | M39: V3 - V2: | O39: 490
I40: OK | L40: Volts | M40: V1 - V3: | O40: 487
I41: OK | L41: Volts | M41: V1 - V2: | O41: 489
B42: ¿ Se verifico el voltaje de salida del contactor de arranque ? | H42: M | I42: OK | L42: Volts | M42: V3 - V2: | O42: 489
I43: OK | L43: Volts | M43: V1 - V3: | O43: 485
...

Sheet Bomba Combustion
Q1: FIRE CONTROL SYSTEMS
Q2: Bucarest 12 Terranova Nogales, Sonora
Q3: Tel. 104-1127 Cel. 631-357-9141 las 24 Hrs.
Q4: Patricia Campos Badillo
Q5: RFC. CABP721117CW7
Q6: E. Mail: firecontrolsystems@hotmail.com
B7: REPORTE DE INSPECCION, PRUEBAS Y MANTENIMIENTO DEL EQUIPO DE BOMBEO DE COMBUSTION
B8: CLIENTE: | C8: Master Lock de Nogales Planta 2 | M8: CONTRATO : | P8: Mensual
B9: ATENCIÓN: | C9: Ing. Julio Landabazo | M9: INSPECTOR : | P9: Santiago Campos
B10: SERVICIO: | C10: ='Tanque Agua'!C10 -> 7 de 12 | M10: FECHA : | P10: ='Tanque Agua'!M10 -> 16 de Julio del 2025
C12: BOMBA PRINCIPAL
B14: f = FRECUENCIA M = MENSUAL Q = TRIMESTRAL A = ANUAL | H14: S: SATISFACTORIO N/A: NO APLICA N: NO SATISFACTORIO
B16: MOTOBOMBA DE COMBUSTION INTERNA. | H16: f | I16: S | J16: N/A | K16: N | L16: PARAMETROS | M16: LECTURAS | P16: COMENTARIOS
B17: ¿ La válvula de succión esta abierta ? | H17: M | I17: OK
B18: ¿ La válvula de descarga esta abierta ? | H18: M | I18: OK
B19: ¿ La válvula de succión abre y cierra correctamente ? | H19: M | I19: OK
B20: ¿ La válvula de descarga abre y cierra correctamente ? | H20: M | I20: OK
B21: ¿ La válvula de succión esta asegurada y/o supervisada ? | H21: M | I21: OK
B22: ¿ La válvula de descarga esta asegurada y/o supervisada ? | H22: M | I22: OK
B23: ¿ La válvula de succión es la adecuada ? | H23: M | I23: OK
B24: ¿ La válvula de descarga es la adecuada ? | H24: M | I24: OK
B25: ¿ Se encontró el selector en automático ? | H25: A | I25: OK | L25: de 15 a 40 | M25: 34 | P25: 45809
B26: ¿ Opera correctamente el Interruptor principal del tablero de control ? | H26: A | I26: OK | L26: de 15 a 40 | M26: 34 | P26: 45809
B27: ¿ Se encontró el equipo en automático ? | H27: M | I27: OK
B28: ¿ Se encontró el foco piloto de automático encendido ? | H28: M | I28: OK
B29: ¿ Se encontraron los focos pilotos de los bancos de baterías encendidos ? | H29: M | I29: OK
B30: ¿ Se encontró el tablero de control cerrado y asegurado ? | H30: M | I30: OK
B31: ¿ El tablero y sus componentes siguen aprobados ? | H31: M | I31: OK | M31: UL FM
B32: ¿ El interruptor de presión es aprobado ? | H32: M | I32: OK | M32: UL CSA
B33: ¿ El cargador de baterías funciona correctamente ? | I33: OK
B34: Banco # 1 | H34: M | I34: OK | L34: VOLTS DC | M34: 13
B35: Banco # 2 | I35: OK | L35: VOLTS DC | M35: 13.2
B36: Verificar el voltaje de alimentación del tablero | H36: M | I36: OK | L36: VOLTS AC | M36: 122.1
B37: ¿ Se encuentra el manómetro de la línea piloto operando ? | H37: M | I37: OK
B38: ¿ Cumple de acuerdo a los estándares la línea piloto ? | H38: M | I38: OK
B39: ¿ Se encuentra en buen estado el acoplamiento mecánico ? | H39: M | I39: OK
B40: ¿ Cuenta con las guardas el acoplamiento mecánico ? | H40: M | I40: OK
B41: ¿ Cuenta con la guarda el volante ? | H41: M | I41: OK
B42: ¿ Cuenta con guarda las bandas ? | H42: M | I42: OK
B43: ¿ El nivel de anticongelante es el adecuado en el motor ? | H43: M | I43: OK
...

Sheet Vàlvulas anual
T1: FIRE CONTROL SYSTEMS
T2: Bucarest 12 Terranova Nogales, Sonora
T3: Tel. 104-1127 Cel. 631-357-9141 las 24 Hrs.
T4: Patricia Campos Badillo
T5: RFC. CABP721117CW7
B6: REPORTE DE INSPECCIÓN, PRUEBAS Y MANTENIMIENTO A VÁLVULAS DE CONTROL Y SECCIONADORAS | T6: firecontrolsystems@hotmail.com
B7: CLIENTE : | D7: Master Lock de Nogales Planta 2 | P7: CONTRATO : | R7: Mensual
B8: ATENCION : | D8: Ing. Julio Landabazo | P8: INSPECTOR : | R8: Santiago Campos
B9: SERVICIO : | D9: ='Tanque Agua'!C10 -> 7 de 12 | P9: FECHA : | R9: 23 de mayo del 2024
D11: Válvulas de Control y Seccionadoras
B13: f = FRECUENCIA M = MENSUAL Q = TRIMESTRAL A = ANUAL | I13: S: SATISFACTORIO N/A: NO APLICA N: NO SATISFACTORIO
B15: LISTA DE REVISION (CHECK LIST):
B16: Dirección | D16: Ubicacion de la Valvula | F16: Area Controlada | J16: Tipo | K16: Abierta | L16: Cerrada | M16: Enllavada | N16: Bloqueada | O16: Monitoreada | P16: Nº Vueltas | Q16: Fecha de Prueba | R16: Observaciones
B17: M-066 | D17: Tanque de Abastecimiento de Agua | F17: Todo el sistema (Succión Bomba Diesel) | J17: OS&V | K17: OK | M17: OK | N17: NO | O17: OK | P17: 34 | Q17: 45809
B18: M-061 | D18: Interior del Cuarto de Bombas | F18: Todo el sistema (Descarga Diesel) | J18: OS&V | K18: OK | M18: OK | N18: NO | O18: OK | P18: 35 | Q18: 45809
B19: N/A | D19: Interior del Cuarto de Bombas | F19: Manifoul de pruebas | J19: OS&V | L19: OK | M19: OK | N19: NO | O19: N/A | P19: N/A | Q19: 45810
B20: N/A | D20: Exterior del Cuarto de Bombas | F20: Succion Bomba Jockey (Todo el Edificio) | J20: Comp. | K20: OK | M20: OK | N20: NO | O20: N/A | P20: 9.75 | Q20: 45811
B21: N/A | D21: Interior del Cuarto de Bombas | F21: Descarga Bomba Jockey (Todo el Edificio) | J21: Comp. | K21: OK | M21: OK | N21: NO | O21: N/A | P21: 8.5 | Q21: 45812
B22: N/A | D22: Interior del Cuarto de Bombas | F22: Sistema de Rociadores Cuarto de Bombas | J22: Comp. | K22: OK | M22: OK | N22: NO | O22: N/A | P22: 9.5 | Q22: 45813
B23: M-092 | D23: Exterior Puerta de emergancia # 11 | F23: Sistema de Rociadores Nº 1 | J23: OS&V | K23: OK | M23: OK | N23: NO | O23: OK | P23: 20.5 | Q23: 45814
B24: M-026 | D24: A un lado salida de emergencia # 11 | F24: Sistema de Rociadores en Racks 1A | J24: IBV | K24: OK | M24: OK | N24: NO | O24: OK | P24: 16.5 | Q24: 45815
D25: Derivacion cabezal sistema 1A | F25: Ampliación Rociadores in rack almacen | J25: IBV | K25: OK | M25: X | N25: NO | O25: OK | P25: 12 | Q25: 45816
B26: M-028 | D26: A un lado salida de emergencia # 11 | F26: Sistema de Rociadores 1B fuera de servicio | J26: IBV | L26: OK | M26: OK | N26: NO | O26: OK | P26: N/A | Q26: 45817 | R26: FUERA DE SERVICIO
B27: M-009 | D27: Exterior Puerta de emergencia Nº 1 | F27: Sistema de Rociadores Nº 2 | J27: OS&V | K27: OK | M27: OK | N27: NO | O27: OK | P27: 20.5 | Q27: 45818
B28: M-007 | D28: En Raiser Sistema 2A | F28: Sistema de Rociadores in Racks 2A | J28: IBV | K28: OK | M28: OK | N28: NO | O28: OK | P28: 16 | Q28: 45819
B29: M-013 | D29: Exterior Puerta de emergencia Nº 2 | F29: Sistema de Rociadores Nº 3 | J29: OS&V | K29: OK | M29: OK | N29: NO | O29: OK | P29: 20.25 | Q29: 45820
B30: M-012 | D30: En Raiser Sistema 3A | F30: Sistema de Rociadores en Racks 3A | J30: IBV | K30: OK | M30: OK | N30: NO | O30: OK | P30: 16 | Q30: 45821
B31: M-020 | D31: Exterior Rampa Automotriz | F31: Sistema de Rociadores Nº 4 | J31: OS&V | K31: OK | M31: OK | N31: NO | O31: OK | P31: 20.5 | Q31: 45822
B32: M-086 | D32: Patio frente area de compresores | F32: Sistema de Rociadores Nº 5 | J32: PIV | K32: OK | M32: OK | N32: NO | O32: OK | P32: 20.5 | Q32: 45823 | R32: requiere lubricación
B33: M-017 | D33: Exterior Cuarto de Bombas | F33: Sistema de Rociadores Nº 6 | J33: OS&V | K33: OK | M33: OK | N33: NO | O33: OK | P33: 20.25 | Q33: 45824
B34: M-021 | D34: Exterior Rampa Automotriz | F34: Sistema de Rociadores Nº 7 | J34: OS&V | L34: OK | M34: OK | N34: NO | O34: OK | P34: N/A | Q34: 45825 | R34: FUERA DE SERVICIO
B35: M-091 | D35: Exterior recepciòn | F35: Sistema de Rociadores Nº 9 | J35: PIV | K35: OK | M35: OK | N35: NO | O35: OK | P35: 20 | Q35: 45826
B36: M-003 | D36: En Raiser Sistema 9 A | F36: Sistema de Rociadores in Racks 9A | J36: IBV | K36: OK | M36: OK | N36: NO | O36: OK | P36: 16.5 | Q36: 45827
B37: M- 034 | D37: Exterior Cocina | F37: Vàlvula Seccionadora (Todo el Edificio) | J37: PIV | L37: OK | M37: OK | N37: NO | O37: OK | P37: xxx | Q37: 45828 | R37: no responde a la manipulación
B38: M-032 | D38: Estacionamiento | F38: Vàlvula Seccionadora (Todo el Edificio) | J38: PIV | K38: OK | M38: OK | N38: NO | O38: OK | P38: 26 | Q38: 45829
B39: M-021 | D39: Exterior Cortina Automotriz | F39: Vàlvula Seccionadora | J39: PIV | K39: OK | M39: OK | N39: NO | O39: OK | P39: 26 | Q39: 45830 | R39: requiere lubricación
B40: M- 029 | D40: Patio Oriente 1 (afuera cuarto de Bombas) | F40: Vàlvula Seccionadora (Todo el Edificio) | J40: PIV | K40: OK | M40: OK | N40: NO | O40: OK | P40: 32.5 | Q40: 45831
B41: M-030 | D41: Patio Oriente 2 (afuera cuarto de Bombas) | F41: Vàlvula Seccionadora (Todo el Edificio) | J41: PIV | K41: OK | M41: OK | N41: NO | O41: OK | P41: 32.75 | Q41: 45832
B42: N/A | D42: Estacionamiento limite de instalaciones | F42: A futuro | J42: PIV | L42: OK | M42: OK | N42: NO | O42: N/A | P42: N/A | Q42: 45833
B43: N/A | D43: Estacionamiento | F43: Interconexion con ITT CANNON | J43: PIV | L43: OK | M43: OK | N43: NO | O43: N/A | P43: N/A | Q43: 45834
...

Sheet Vàlvulas
R1: FIRE CONTROL SYSTEMS
R2: Bucarest 12 Terranova Nogales, Sonora
R3: Tel. 104-1127 Cel. 631-357-9141 las 24 Hrs.
R4: Patricia Campos Badillo
R5: RFC. CABP721117CW7
B6: REPORTE DE INSPECCIÓN, PRUEBAS Y MANTENIMIENTO A VÁLVULAS DE CONTROL Y SECCIONADORAS | R6: firecontrolsystems@hotmail.com
B7: CLIENTE : | D7: Master Lock de Nogales Planta 2 | O7: CONTRATO : | P7: Mensual
B8: ATENCION : | D8: Ing. Julio Landabazo | O8: INSPECTOR : | P8: Santiago Campos
B9: SERVICIO : | D9: ='Tanque Agua'!C10 -> 7 de 12 | O9: FECHA : | P9: 16 de julio del 2025
D11: Válvulas de Control y Seccionadoras
B13: f = FRECUENCIA M = MENSUAL Q = TRIMESTRAL A = ANUAL | I13: S: SATISFACTORIO N/A: NO APLICA N: NO SATISFACTORIO
B15: LISTA DE REVISION (CHECK LIST):
B16: Dirección | D16: Ubicacion de la Valvula | F16: Area Controlada | J16: Tipo | K16: Abierta | L16: Cerrada | M16: Enllavada | N16: Bloqueada | O16: Monitoreada | P16: Observaciones
B17: M-066 | D17: Tanque de Abastecimiento de Agua | F17: Todo el sistema (Succión Bomba Diesel) | J17: OS&V | K17: OK | M17: OK | N17: NO | O17: OK
B18: M-061 | D18: Interior del Cuarto de Bombas | F18: Todo el sistema (Descarga Diesel) | J18: OS&V | K18: OK | M18: OK | N18: NO | O18: OK
B19: N/A | D19: Interior del Cuarto de Bombas | F19: Manifoul de pruebas | J19: OS&V | L19: OK | M19: OK | N19: NO | O19: N/A
B20: N/A | D20: Exterior del Cuarto de Bombas | F20: Succion Bomba Jockey (Todo el Edificio) | J20: Comp. | K20: OK | M20: OK | N20: NO | O20: N/A
B21: N/A | D21: Interior del Cuarto de Bombas | F21: Descarga Bomba Jockey (Todo el Edificio) | J21: Comp. | K21: OK | M21: OK | N21: NO | O21: N/A
B22: N/A | D22: Interior del Cuarto de Bombas | F22: Sistema de Rociadores Cuarto de Bombas | J22: Comp. | K22: OK | M22: OK | N22: NO | O22: N/A
B23: M-092 | D23: Exterior Puerta de emergancia # 11 | F23: Sistema de Rociadores Nº 1 | J23: OS&V | K23: OK | M23: OK | N23: NO | O23: OK
B24: M-026 | D24: A un lado salida de emergencia # 11 | F24: Sistema de Rociadores en Racks 1A | J24: IBV | K24: OK | M24: OK | N24: NO | O24: OK
B25: M-028 | D25: A un lado salida de emergencia # 11 | F25: Sistema de Rociadores 1B | J25: IBV | L25: OK | M25: OK | N25: NO | O25: X | P25: FUERA DE SERVICIO
B26: M-009 | D26: Exterior Puerta de emergencia Nº 1 | F26: Sistema de Rociadores Nº 2 | J26: OS&V | K26: OK | M26: OK | N26: NO | O26: OK
B27: M-007 | D27: En Raiser Sistema 2A | F27: Sistema de Rociadores in Racks 2A | J27: IBV | K27: OK | M27: OK | N27: NO | O27: OK
B28: M-013 | D28: Exterior Puerta de emergencia Nº 2 | F28: Sistema de Rociadores Nº 3 | J28: OS&V | K28: OK | M28: OK | N28: NO | O28: OK
B29: M-012 | D29: En Raiser Sistema 3A | F29: Sistema de Rociadores en Racks 3A | J29: IBV | K29: OK | M29: OK | N29: NO | O29: OK
B30: M-017 | D30: Exterior Cuarto de Bombas | F30: Sistema de Rociadores Nº 6 | J30: OS&V | K30: OK | M30: OK | N30: NO | O30: OK
B31: M-086 | D31: Patio frente area de compresores | F31: Sistema de Rociadores Nº 5 | J31: PIV | K31: OK | M31: OK | N31: NO | O31: OK | P31: requiere lubricación cada mes
B32: M-020 | D32: Exterior Rampa Automotriz | F32: Sistema de Rociadores Nº 4 | J32: OS&V | K32: OK | M32: OK | N32: NO | O32: OK
B33: M-021 | D33: Exterior Rampa Automotriz | F33: Sistema de Rociadores Nº 7 | J33: OS&V | L33: OK | M33: OK | N33: NO | O33: OK | P33: FUERA DE SERVICIO
B34: M-091 | D34: Exterior recepciòn | F34: Sistema de Rociadores Nº 9 | J34: PIV | K34: OK | M34: OK | N34: NO | O34: OK
B35: M-003 | D35: En Raiser Sistema 9 A | F35: Sistema de Rociadores in Racks 9A | J35: IBV | K35: OK | M35: OK | N35: NO | O35: OK
B36: M- 090 | D36: Derivacion cabezal sistema 1A | F36: Ampliación Rociadores in rack almacen | J36: IBV | K36: OK | M36: X | N36: NO | O36: OK
B37: N/A | D37: Estacionamiento | F37: Interconexion con ITT CANNON | J37: PIV | L37: OK | M37: OK | N37: NO | O37: N/A
B38: N/A | D38: Patio noroeste | F38: Interconexion con ITT CANNON | J38: PIV | L38: OK | M38: OK | N38: NO | O38: N/A
B39: M-021 | D39: Exterior Cortina Automotriz | F39: Vàlvula Seccionadora | J39: PIV | K39: OK | M39: OK | N39: NO | O39: OK
B40: M- 029 | D40: Patio Oriente 1 (afuera cuarto de Bombas) | F40: Vàlvula Seccionadora (Todo el Edificio) | J40: PIV | K40: OK | M40: OK | N40: NO | O40: OK
B41: M-030 | D41: Patio Oriente 2 (afuera cuarto de Bombas) | F41: Vàlvula Seccionadora (Todo el Edificio) | J41: PIV | K41: OK | M41: OK | N41: NO | O41: OK
B42: N/A | D42: Estacionamiento limite de instalaciones | F42: A futuro | J42: PIV | L42: OK | M42: OK | N42: NO | O42: N/A
B43: M- 034 | D43: Exterior Cocina | F43: Vàlvula Seccionadora (Todo el Edificio) | J43: PIV | L43: OK | M43: OK | N43: NO | O43: OK | P43: no responde a la manipulación
...

Sheet Hidrantes Exteriores
T1: FIRE CONTROL SYSTEMS
T2: Bucarest 12 Terranova Nogales, Sonora
T3: Tel. 104-1127 Cel. 631-357-9141 las 24 Hrs.
T4: Patricia Campos Badillo
T5: RFC. CABP721117CW7
B6: REPORTE DE INSPECCION, PRUEBAS Y MANTENIMIENTO A SISTEMAS DE HIDRANTES EXTERIORES | T6: firecontrolsystems@hotmail.com
B7: CLIENTE: | C7: Master Lock de Nogales Planta 2 | O7: CONTRATO : | R7: Mensual
B8: ATENCIÓN: | C8: Ing. Julio Landabazo | O8: INSPECTOR : | R8: Santiago Campos
B9: SERVICIO: | C9: ='Tanque Agua'!C10 -> 7 de 12 | O9: FECHA : | R9: ='Tanque Agua'!M10 -> 16 de Julio del 2025
C11: HIDRANTES EXTERIORES
C13: SATISFACTORIO : | E13: OK | H13: NO SATISFACTORIO : | L13: X | M13: NO APLICA : | S13: N/A
G15: NUMERO DE HIDRANTE : | H15: 1 | I15: 2 | J15: 3 | K15: 4 | L15: 5 | M15: 6 | N15: 7 | O15: 8 | P15: 9 | Q15: 10
B17: HIDRANTES EXTERIORES | R17: Comentarios
B18: ¿ El sistema se encontró en servicio ? | H18: OK | I18: OK | J18: OK | K18: OK | L18: OK | M18: OK | N18: OK | O18: OK | P18: OK | Q18: OK
B19: ¿ La válvula de control esta libre de fugas en posición de abierto ? | H19: OK | I19: OK | J19: OK | K19: OK | L19: OK | M19: OK | N19: OK | O19: OK | P19: OK | Q19: OK
B20: ¿ El hidrante presenta fugas ? | H20: OK | I20: OK | J20: OK | K20: OK | L20: OK | M20: OK | N20: OK | O20: OK | P20: OK | Q20: OK
B21: ¿ Tiene tapones las salidas del hidrante ? | H21: OK | I21: OK | J21: OK | K21: OK | L21: OK | M21: OK | N21: OK | O21: OK | P21: OK | Q21: OK
B22: ¿ El área del hidrante esta libre y despejada ? | H22: OK | I22: OK | J22: OK | K22: OK | L22: OK | M22: OK | N22: OK | O22: OK | P22: OK | Q22: OK
B23: ¿ Es fácil el acceso hacia el hidrante ? | H23: OK | I23: OK | J23: OK | K23: OK | L23: OK | M23: OK | N23: OK | O23: OK | P23: OK | Q23: OK
B24: ¿ El hidrante es visible a distancia ? | H24: OK | I24: OK | J24: OK | K24: OK | L24: OK | M24: OK | N24: OK | O24: OK | P24: OK | Q24: OK
B25: ¿ El hidrante cuenta con identificación ? | H25: OK | I25: OK | J25: OK | K25: OK | L25: OK | M25: OK | N25: OK | O25: OK | P25: OK | Q25: OK
B26: ¿ Al abrir el hidrante presenta fuga por los tapones ? | H26: OK | I26: OK | J26: OK | K26: OK | L26: OK | M26: OK | N26: OK | O26: OK | P26: OK | Q26: OK
B27: ¿ Los dispositivos están en buenas condiciones físicas ? | H27: OK | I27: OK | J27: OK | K27: OK | L27: X | M27: X | N27: X | O27: OK | P27: OK | Q27: OK
B28: ¿ Se encuentran las salidas equipadas con adaptador reductor de manguera? | H28: OK | I28: OK | J28: OK | K28: OK | L28: OK | M28: OK | N28: OK | O28: OK | P28: OK | Q28: OK
B29: ¿ El hidrante cuenta con un gabinete de mangueras cercano ? | H29: OK | I29: OK | J29: OK | K29: OK | L29: OK | M29: OK | N29: OK | O29: OK | P29: OK | Q29: OK
... B39: ¿ Las características de la manguera son las adecuadas para el riesgo ? | H39: OK | I39: OK | J39: OK | K39: OK | L39: OK | M39: OK | N39: OK | O39: OK | P39: OK | Q39: OK
B40: ¿ Resulto satisfactoria la prueba hidrostática a la manguera ? | G40: 5 años | H40: X | I40: X | J40: X | K40: X | L40: X | M40: X | N40: X | O40: X | P40: X | Q40: X | R40: 45231
B41: ¿ Se realizo flusheo del Hidrante ? | H41: OK | I41: OK | J41: OK | K41: OK | L41: OK | M41: OK | N41: OK | O41: OK | P41: OK | Q41: OK | R41: 45342
B43: OBSERVACIONES:
B45: Gabinete en estacionamiento tiene la manguera dañada.
G51: ELABORO :
G52: =R8 -> Santiago Campos
G54: =R9 -> 16 de Julio del 2025
G55: NOMBRE, FIRMA Y FECHA

Sheet Hidrantes Interiores
S1: FIRE CONTROL SYSTEMS
S2: Bucarest 12 Terranova Nogales, Sonora
S3: Tel. 104-1127 Cel. 631-357-9141 las 24 Hrs.
S4: Patricia Campos Badillo
S5: RFC. CABP721117CW7
B6: REPORTE MENSUAL DE INSPECCION, PRUEBAS Y MANTENIMIENTO A SISTEMAS DE HIDRANTES INTERIORES | S6: E. Mail: firecontrolsystems@hotmail.com
B7: CLIENTE: | C7: Master de Nogales Planta 2 | P7: CONTRATO : | S7: Mensual
B8: ATENCIÓN: | C8: Ing. Julio Landabazo | P8: INSPECTOR : | S8: Santiago Campos
B9: SERVICIO: | C9: ='Tanque Agua'!C10 -> 7 de 12 | P9: FECHA : | S9: 17 de Julio del 2025
C11: SATISFACTORIO : | E11: OK | G11: NO SATISFACTORIO : | K11: X | L11: NO APLICA : | R11: N/A
G13: 1 | H13: 2 | I13: 3 | J13: 4 | K13: 5 | L13: 6 | M13: 7 | N13: 8 | O13: 9 | P13: 10 | Q13: 11 | R13: 12
B14: HIDRANTES INTERIORES | S14: Observaciones
B15: ¿ El sistema se encontró en servicio ? | G15: OK | H15: OK | I15: OK | J15: OK | K15: OK | L15: OK | M15: OK | N15: OK | O15: OK | P15: OK | Q15: OK | R15: OK
B16: ¿ Funciona el detector de flujo ? | G16: OK | H16: OK | I16: OK | J16: OK | K16: OK | L16: OK | M16: OK | N16: OK | O16: OK | P16: OK | Q16: OK | R16: OK
B17: ¿ Funciona el supervisor de válvula ? | G17: OK | H17: OK | I17: OK | J17: OK | K17: OK | L17: OK | M17: OK | N17: OK | O17: OK | P17: OK | Q17: OK | R17: OK
B18: ¿ Funciona la válvula de alarma del sistema ? | G18: OK | H18: OK | I18: OK | J18: OK | K18: OK | L18: OK | M18: OK | N18: OK | O18: OK | P18: OK | Q18: OK | R18: OK
B19: ¿ La válvula de control esta libre de fugas en posición de abierto ? | G19: OK | H19: OK | I19: OK | J19: OK | K19: OK | L19: OK | M19: OK | N19: OK | O19: OK | P19: OK | Q19: OK | R19: OK
B20: ¿ El área del hidrante esta libre y despejada ? | G20: OK | H20: OK | I20: OK | J20: OK | K20: OK | L20: OK | M20: OK | N20: OK | O20: OK | P20: OK | Q20: OK | R20: OK
B21: ¿ Es fácil el acceso hacia el hidrante ? | G21: OK | H21: OK | I21: OK | J21: OK | K21: OK | L21: OK | M21: OK | N21: OK | O21: OK | P21: OK | Q21: OK | R21: Ok
B22: ¿ El hidrante es visible a distancia ? | G22: OK | H22: OK | I22: OK | J22: OK | K22: OK | L22: OK | M22: OK | N22: OK | O22: OK | P22: OK | Q22: OK | R22: OK
B23: ¿ El hidrante cuenta con identificación ? | G23: OK | H23: OK | I23: OK | J23: OK | K23: OK | L23: OK | M23: OK | N23: OK | O23: OK | P23: OK | Q23: OK | R23: OK
B24: ¿ Las conexiones del dren se encuentran libres de fugas ? | G24: OK | H24: OK | I24: OK | J24: OK | K24: OK | L24: OK | M24: OK | N24: OK | O24: OK | P24: OK | Q24: OK | R24: OK
B25: ¿ La válvula de la manguera se encuentra libre de daño físico ? | G25: OK | H25: OK | I25: OK | J25: OK | K25: OK | L25: OK | M25: OK | N25: OK | O25: OK | P25: OK | Q25: OK | R25: OK | V25: de
B26: ¿ La soportería es la adecuada ? | G26: OK | H26: OK | I26: OK | J26: OK | K26: OK | L26: OK | M26: OK | N26: OK | O26: OK | P26: OK | Q26: OK | R26: OK
B27: ¿ Se encuentra sin daño la manguera ? | G27: OK | H27: OK | I27: OK | J27: OK | K27: OK | L27: OK | M27: OK | N27: OK | O27: OK | P27: OK | Q27: OK | R27: OK
B28: ¿ Cuenta con empaques las conexiones de la manguera ? | G28: OK | H28: OK | I28: OK | J28: OK | K28: OK | L28: OK | M28: OK | N28: OK | O28: OK | P28: OK | Q28: OK | R28: OK
B29: ¿ El hidrante cuenta con llave para acoplamiento? | G29: X | H29: X | I29: X | J29: X | K29: X | L29: X | M29: X | N29: X | O29: X | P29: X | Q29: X | R29: X
B30: ¿ El chiflón se encuentra en buen estado ? | G30: OK | H30: OK | I30: OK | J30: OK | K30: OK | L30: OK | M30: OK | N30: OK | O30: OK | P30: OK | Q30: OK | R30: OK
B31: ¿ El chiflón opera suavemente todo el rango de apertura y cierre ? | G31: OK | H31: OK | I31: OK | J31: OK | K31: OK | L31: OK | M31: OK | N31: OK | O31: OK | P31: OK | Q31: OK | R31: OK
B32: ¿ Esta conectada la manguera ? | G32: OK | H32: OK | I32: OK | J32: OK | K32: OK | L32: OK | M32: OK | N32: OK | O32: OK | P32: OK | Q32: OK | R32: OK
B33: ¿ Son compatibles las cuerdas del cople, la manguera y el chiflón ? | G33: OK | H33: OK | I33: OK | J33: OK | K33: OK | L33: OK | M33: OK | N33: OK | O33: OK | P33: OK | Q33: OK | R33: OK
B34: ¿ Esta la manguera doblada o enrollada correctamente ? | G34: OK | H34: OK | I34: OK | J34: OK | K34: OK | L34: OK | M34: OK | N34: OK | O34: OK | P34: OK | Q34: OK | R34: OK
B35: ¿ El carrete gira libremente ? | G35: OK | H35: OK | I35: OK | J35: OK | K35: OK | L35: OK | M35: OK | N35: OK | O35: OK | P35: X | Q35: OK | R35: OK
B36: ¿ El carrete presenta daños o golpes ? | G36: OK | H36: OK | I36: OK | J36: OK | K36: OK | L36: OK | M36: OK | N36: OK | O36: OK | P36: X | Q36: OK | R36: OK
B37: ¿ Las características de la manguera son las adecuadas para el riesgo ? | G37: OK | H37: OK | I37: OK | J37: OK | K37: OK | L37: OK | M37: OK | N37: OK | O37: OK | P37: OK | Q37: OK | R37: OK
B38: ¿ Resulto satisfactoria la prueba hidrostática a la manguera ? | G38: OK | H38: OK | I38: X | J38: OK | K38: OK | L38: OK | M38: OK | N38: OK | O38: X | P38: X | Q38: X | R38: OK | S38: oct-nov 2023
B40: OBSERVACIONES:
B41: Todos los hidrantes carecen de llave para coples
B42: Hidrantes No. 3, 9, 10 y 11 tras realizarles pruebas hidrostáticas el resultado no fue satisfactorio.
G47: ELABORO :
...

Sheet Hidrantes Interiores (2)
S1: FIRE CONTROL SYSTEMS
S2: Bucarest 12 Terranova Nogales, Sonora
S3: Tel. 104-1127 Cel. 631-357-9141 las 24 Hrs.
S4: Patricia Campos Badillo
S5: RFC. CABP721117CW7
B6: REPORTE MENSUAL DE INSPECCION, PRUEBAS Y MANTENIMIENTO A SISTEMAS DE HIDRANTES INTERIORES | S6: E. Mail: firecontrolsystems@hotmail.com
B7: CLIENTE: | C7: Master de Nogales Planta 2 | L7: CONTRATO : | O7: Mensual
B8: ATENCIÓN: | C8: Ing. Julio Landabazo | L8: INSPECTOR : | O8: ='Hidrantes Interiores'!S8 -> Santiago Campos
B9: SERVICIO: | C9: ='Tanque Agua'!C10 -> 7 de 12 | L9: FECHA : | O9: ='Hidrantes Interiores'!S9 -> 17 de Julio del 2025
C11: SATISFACTORIO : | D11: OK | F11: NO SATISFACTORIO : | G11: X | K11: NO APLICA : | N11: N/A
G13: 13 | H13: 14 | I13: 15 | J13: 16 | K13: 17 | L13: 18 | M13: 19 | N13: 20 | O13: 21 | P13: 22
B14: HIDRANTES INTERIORES | Q14: Observaciones
B15: ¿ El sistema se encontró en servicio ? | G15: OK | H15: OK | I15: OK | J15: OK | K15: OK | L15: OK | M15: OK | N15: OK | O15: OK | P15: OK
B16: ¿ Funciona el detector de flujo ? | G16: OK | H16: OK | I16: OK | J16: OK | K16: OK | L16: OK | M16: OK | N16: OK | O16: OK | P16: OK
B17: ¿ Funciona el supervisor de válvula ? | G17: OK | H17: OK | I17: OK | J17: OK | K17: OK | L17: OK | M17: OK | N17: OK | O17: OK | P17: OK
B18: ¿ Funciona la válvula de alarma del sistema ? | G18: OK | H18: OK | I18: OK | J18: OK | K18: OK | L18: OK | M18: OK | N18: OK | O18: OK | P18: OK
B19: ¿ La válvula de control esta libre de fugas en posición de abierto ? | G19: OK | H19: OK | I19: OK | J19: OK | K19: OK | L19: OK | M19: OK | N19: OK | O19: OK | P19: OK
B20: ¿ El área del hidrante esta libre y despejada ? | G20: OK | H20: OK | I20: OK | J20: X | K20: OK | L20: OK | M20: Ok | N20: OK | O20: OK | P20: OK
B21: ¿ Es fácil el acceso hacia el hidrante ? | G21: OK | H21: OK | I21: OK | J21: X | K21: OK | L21: OK | M21: X | N21: OK | O21: OK | P21: OK
B22: ¿ El hidrante es visible a distancia ? | G22: OK | H22: OK | I22: OK | J22: X | K22: OK | L22: OK | M22: X | N22: OK | O22: OK | P22: OK
B23: ¿ El hidrante cuenta con identificación ? | G23: OK | H23: OK | I23: OK | J23: OK | K23: X | L23: OK | M23: X | N23: OK | O23: OK | P23: OK
B24: ¿ Las conexiones del dren se encuentran libres de fugas ? | G24: OK | H24: OK | I24: OK | J24: OK | K24: OK | L24: OK | M24: OK | N24: OK | O24: OK | P24: OK
B25: ¿ La válvula de la manguera se encuentra libre de daño físico ? | G25: OK | H25: OK | I25: OK | J25: OK | K25: OK | L25: OK | M25: OK | N25: OK | O25: OK | P25: OK
B26: ¿ La soportería es la adecuada ? | G26: OK | H26: OK | I26: OK | J26: OK | K26: OK | L26: OK | M26: OK | N26: OK | O26: OK | P26: OK
... B37: ¿ Las características de la manguera son las adecuadas para el riesgo ? | G37: OK | H37: OK | I37: OK | J37: OK | K37: OK | L37: OK | M37: OK | N37: OK | O37: OK | P37: OK
B38: ¿ Resulto satisfactoria la prueba hidrostática a la manguera ? | G38: OK | H38: X | I38: OK | J38: OK | K38: OK | L38: OK | M38: OK | N38: OK | O38: OK | P38: OK | Q38: oct-nov 2023
B40: OBSERVACIONES :
B42: Todos los hidrantes carecen de llave para coples
B43: Hidrantes Nº 14,16 y 20 no giran bien debido a que están dentro de racks
B44: Hidrantes Nº 16 y 19 no cuenta con ID
B45: Hidrante No. 19 tiene el chiflon dañado no enrosca totalmente en la manguera.
B46: Al realizar pruebas hidritaticas a las mangueras de los hidrantes, la manguera del Hidrante N° 14 resultó con daños, se debe reemplazar.
G49: ELABORO :
G50: =O8 -> Santiago Campos
G52: =O9 -> 17 de Julio del 2025
G53: NOMBRE, FIRMA Y FECHA

Sheet Sistema 1
P1: FIRE CONTROL SYSTEMS
P2: Bucarest 12 Terranova Nogales, Sonora
P3: Tel. 104-1127 Cel. 631-357-9141 las 24 Hrs.
P4: Patricia Campos Badillo
P5: RFC. CABP721117CW7
B6: REPORTE DE INSPECCION, PRUEBAS Y MANTENIMIENTO A SISTEMAS DE ROCIADORES | P6: E. Mail: firecontrolsystems@hotmail.com
B7: CLIENTE: | C7: Master Lock de Nogales Planta 2 | J7: CONTRATO : | L7: Mensual
B8: ATENCIÓN: | C8: Ing. Julio Landabazo | J8: INSPECTOR : | L8: ='Hidrantes Interiores'!S8 -> Santiago Campos
B9: SERVICIO: | C9: ='Tanque Agua'!C10 -> 7 de 12 | J9: FECHA : | L9: 17 de Julio del 2025
C11: Sistema Nº 1
B13: f = FRECUENCIA M = MENSUAL Q = TRIMESTRAL A = ANUAL | G13: S: SATISFACTORIO N/A: NO APLICA N: NO SATISFACTORIO
B15: SISTEMAS HUMEDOS | G15: f | H15: S | I15: N/A | J15: N | K15: PARAMETROS | L15: LECTURAS | O15: COMENTARIOS
B16: ¿ El sistema se encontró en servicio ? | G16: M | H16: OK
B17: ¿ El stock de rociadores es el adecuado en cantidad y temperatura ? | G17: M | H17: OK | L17: 286ºF - K=11.2
B18: ¿ Se cuenta con las llaves adecuadas de los rociadores ? | G18: M | H18: OK
B19: Cantidad de rociadores instalados de acuerdo al diseño original. | G19: M | H19: OK | L19: 478
B20: ¿ No se han realizado modificaciones en el área protegida con relación al plano del diseño original ? | G20: M | H20: OK
B21: ¿ La válvula hacia los hidrantes esta abierta ? | G21: M | H21: OK
B22: ¿ La válvula hacia los hidrantes esta asegurada y/o supervisada ? | G22: M | H22: OK
B23: ¿ La válvula de control esta accesible ? | G23: M | H23: OK
B24: ¿ La válvula OS&Y opera al cerrarla y retorna a la posición de abierto ? | G24: M | H24: OK
B25: ¿ La válvula de control cierra y retorna a la posición de abierto ? | G25: M | H25: OK
B26: ¿ La válvula de control esta supervisada y/o asegurada ? | G26: M | H26: OK
B27: ¿ Operan los supervisores de válvula ? | G27: M | H27: OK
B28: ¿ Esta delimitada el área del riser del sistema ? | G28: M | H28: OK
B29: ¿ Las válvulas check mantienen la presión ? | G29: M | H29: OK
B30: ¿ La válvula de alarma esta en buen estado ? | G30: M | H30: OK
B31: ¿ La válvula de alarma mantiene la presión ? | G31: M | H31: OK
B32: Presión en la línea de alimentación | G32: M | H32: OK | K32: Psi | L32: 155
B33: ¿ La presión de alimentación es adecuada ? | G33: M | H33: Ok
B34: Presión en la línea de rociadores | G34: M | H34: OK | K34: Psi | L34: 160
B35: ¿ La presión del sistema es adecuada ? | G35: M | H35: OK
B36: ¿ Coincide la lectura de los manómetros del riser con el manómetro certificado ? | G36: M | H36: OK
B37: ¿ La válvula de alivio opera adecuadamente ? | G37: M | H37: OK
B38: ¿ Las válvulas reguladora de presión esta abierta ? | G38: M | H38: OK
B39: ¿ Las válvulas reguladora de presión esta en buenas condiciones ? | G39: M | H39: OK
B40: ¿ Las válvulas reguladora de presión esta ajustada de acuerdo al criterio del diseño ? | G40: M | H40: OK | K40: Psi | L40: 175
B41: ¿ La válvula del drene opera adecuadamente ? | G41: M | H41: OK
B42: ¿ El detector de flujo y/o de Presión opera ? | G42: M | H42: OK
B43: ¿ La válvula de alivio del la línea de inspección opera ? | G43: M | H43: OK
...

Sheet Sistema 1A
P1: FIRE CONTROL SYSTEMS
P2: Bucarest 12 Terranova Nogales, Sonora
P3: Tel. 104-1127 Cel. 631-357-9141 las 24 Hrs.
P4: Patricia Campos Badillo
P5: RFC. CABP721117CW7
B6: REPORTE DE INSPECCION, PRUEBAS Y MANTENIMIENTO A SISTEMAS DE ROCIADORES | P6: E. Mail: firecontrolsystems@hotmail.com
B7: CLIENTE: | C7: Master Lock de Nogales Planta 2 | J7: CONTRATO : | L7: Mensual
B8: ATENCIÓN: | C8: Ing. Julio Landabazo | J8: INSPECTOR : | L8: ='Hidrantes Interiores'!S8 -> Santiago Campos
B9: SERVICIO: | C9: ='Tanque Agua'!C10 -> 7 de 12 | J9: FECHA : | L9: ='Sistema 1'!L9 -> 17 de Julio del 2025
C11: Sistema Nº 1A In Rack
B13: f = FRECUENCIA M = MENSUAL Q = TRIMESTRAL A = ANUAL | G13: S: SATISFACTORIO N/A: NO APLICA N: NO SATISFACTORIO
B15: SISTEMAS HUMEDOS | G15: f | H15: S | I15: N/A | J15: N | K15: PARAMETROS | L15: LECTURAS | O15: COMENTARIOS
B16: ¿ El sistema se encontró en servicio ? | G16: M | H16: OK
B17: ¿ El stock de rociadores es el adecuado en cantidad y temperatura ? | G17: M | H17: OK | L17: 165ºf
B18: ¿ Se cuenta con las llaves adecuadas de los rociadores ? | G18: M | H18: OK
B19: Cantidad de rociadores instalados de acuerdo al diseño original. | G19: M | H19: OK | M19: 234
B20: ¿ No se han realizado modificaciones en el área protegida con relación al plano del diseño original ? | G20: M | H20: OK
B21: ¿ La válvula de control esta accesible ? | G21: M | H21: OK
B22: ¿ La válvula OS&Y opera al cerrarla y retorna a la posición de abierto ? | G22: M | H22: OK
B23: ¿ La válvula de control cierra y retorna a la posición de abierto ? | G23: M | H23: OK
B24: ¿ La válvula de control esta supervisada y/o asegurada ? | G24: M | H24: OK
B25: ¿ Operan los supervisores de válvula ? | G25: M | H25: OK
B26: ¿ Esta delimitada el área del riser del sistema ? | G26: M | H26: OK
B27: ¿ Las válvulas check mantienen la presión ? | G27: M | H27: OK
B28: ¿ La válvula de alarma esta en buen estado ? | G28: M | H28: OK
B29: ¿ La válvula de alarma mantiene la presión ? | G29: M | H29: OK
B30: Presión en la línea de alimentación | G30: M | H30: OK | K30: Psi | L30: 155
B31: ¿ La presión de alimentación es adecuada ? | G31: M | H31: OK
B32: Presión en la línea de rociadores | G32: M | H32: OK | K32: Psi | L32: 155
B33: ¿ La presión del sistema es adecuada ? | G33: M | H33: OK
B34: ¿ Coincide la lectura de los manómetros del riser con el manómetro certificado ? | G34: M | H34: OK
B35: ¿ La válvula de alivio opera adecuadamente ? | G35: M | H35: OK
B36: ¿ Las válvulas reguladora de presión esta abierta ? | G36: M | H36: OK
B37: ¿ Las válvulas reguladora de presión esta en buenas condiciones ? | G37: M | H37: OK
B38: ¿ Las válvulas reguladora de presión esta ajustada de acuerdo al criterio del diseño ? | G38: M | H38: OK | K38: Psi | M38: 175
B39: ¿ La válvula del drene opera adecuadamente ? | G39: M | H39: OK
B40: ¿ El detector de flujo y/o de Presión opera ? | G40: M | H40: OK
B41: ¿ La válvula de alivio del la línea de inspección opera ? | G41: M | H41: OK
B42: ¿ Las guardas de los rociadores son las aprobadas ? | G42: M | H42: OK | K42: UL o FM
B43: ¿ Los rociadores están libres de daños y fugas ? | G43: M | H43: OK
...

Sheet Sistema 2 
P1: FIRE CONTROL SYSTEMS
P2: Bucarest 12 Terranova Nogales, Sonora
P3: Tel. 104-1127 Cel. 631-357-9141 las 24 Hrs.
P4: Patricia Campos Badillo
P5: RFC. CABP721117CW7
B6: REPORTE DE INSPECCION, PRUEBAS Y MANTENIMIENTO A SISTEMAS DE ROCIADORES | P6: E. Mail: firecontrolsystems@hotmail.com
B7: CLIENTE: | C7: Master Lock de Nogales Planta 2 | J7: CONTRATO : | L7: Mensual
B8: ATENCIÓN: | C8: Ing. Julio Landabazo | J8: INSPECTOR : | L8: ='Hidrantes Interiores'!S8 -> Santiago Campos
B9: SERVICIO: | C9: ='Tanque Agua'!C10 -> 7 de 12 | J9: FECHA : | L9: ='Sistema 1'!L9 -> 17 de Julio del 2025
C11: Sistema Nº 2
B13: f = FRECUENCIA M = MENSUAL Q = TRIMESTRAL A = ANUAL | G13: S: SATISFACTORIO N/A: NO APLICA N: NO SATISFACTORIO
B15: SISTEMAS HUMEDOS | G15: f | H15: S | I15: N/A | J15: N | K15: PARAMETROS | L15: LECTURAS | O15: COMENTARIOS
B16: ¿ El sistema se encontró en servicio ? | G16: M | H16: OK
B17: ¿ El stock de rociadores es el adecuado en cantidad y temperatura ? | G17: M | H17: OK | L17: 286ºF - K=11.2
B18: ¿ Se cuenta con las llaves adecuadas de los rociadores ? | G18: M | H18: OK
B19: Cantidad de rociadores instalados de acuerdo al diseño original. | G19: M | H19: OK | M19: 458
B20: ¿ No se han realizado modificaciones en el área protegida con relación al plano del diseño original ? | G20: M | H20: OK
B21: ¿ La válvula hacia los hidrantes esta abierta ? | G21: M | H21: OK
B22: ¿ La válvula hacia los hidrantes esta asegurada y/o supervisada ? | G22: M | H22: OK
B23: ¿ La válvula de control esta accesible ? | G23: M | H23: OK
B24: ¿ La válvula OS&Y opera al cerrarla y retorna a la posición de abierto ? | G24: M | H24: OK
B25: ¿ La válvula de control cierra y retorna a la posición de abierto ? | G25: M | H25: OK
B26: ¿ La válvula de control esta supervisada y/o asegurada ? | G26: M | H26: OK
B27: ¿ Operan los supervisores de válvula ? | G27: M | H27: OK
B28: ¿ Esta delimitada el área del riser del sistema ? | G28: M | H28: OK
B29: ¿ Las válvulas check mantienen la presión ? | G29: M | H29: OK
B30: ¿ La válvula de alarma esta en buen estado ? | G30: M | H30: OK
B31: ¿ La válvula de alarma mantiene la presión ? | G31: M | H31: OK
B32: Presión en la línea de alimentación | G32: M | H32: OK | K32: Psi | L32: 150
B33: ¿ La presión de alimentación es adecuada ? | G33: M | H33: OK
B34: Presión en la línea de rociadores | G34: M | H34: OK | K34: Psi | L34: 165
B35: ¿ La presión del sistema es adecuada ? | G35: M | H35: OK
B36: ¿ Coincide la lectura de los manómetros del riser con el manómetro certificado ? | G36: M | H36: OK
B37: ¿ La válvula de alivio opera adecuadamente ? | G37: M | H37: OK
B38: ¿ Las válvulas reguladora de presión esta abierta ? | G38: M | H38: OK
B39: ¿ Las válvulas reguladora de presión esta en buenas condiciones ? | G39: M | H39: OK
B40: ¿ Las válvulas reguladora de presión esta ajustada de acuerdo al criterio del diseño ? | G40: M | H40: OK | K40: Psi | M40: 175
B41: ¿ La válvula del drene opera adecuadamente ? | G41: M | H41: OK
B42: ¿ El detector de flujo y/o de Presión opera ? | G42: M | H42: OK
B43: ¿ La válvula de alivio del la línea de inspección opera ? | G43: M | H43: OK
...

Sheet Sistema 2A 
P1: FIRE CONTROL SYSTEMS
P2: Bucarest 12 Terranova Nogales, Sonora
P3: Tel. 104-1127 Cel. 631-357-9141 las 24 Hrs.
P4: Patricia Campos Badillo
P5: RFC. CABP721117CW7
B6: REPORTE DE INSPECCION, PRUEBAS Y MANTENIMIENTO A SISTEMAS DE ROCIADORES | P6: E. Mail: firecontrolsystems@hotmail.com
B7: CLIENTE: | C7: Master Lock de Nogales Planta 2 | J7: CONTRATO : | L7: Mensual
B8: ATENCIÓN: | C8: Ing.Julio Landabazo | J8: INSPECTOR : | L8: ='Hidrantes Interiores'!S8 -> Santiago Campos
B9: SERVICIO: | C9: ='Tanque Agua'!C10 -> 7 de 12 | J9: FECHA : | L9: ='Sistema 1'!L9 -> 17 de Julio del 2025
C11: Sistema Nº 2A In Rack
B13: f = FRECUENCIA M = MENSUAL Q = TRIMESTRAL A = ANUAL | G13: S: SATISFACTORIO N/A: NO APLICA N: NO SATISFACTORIO
B15: SISTEMAS HUMEDOS | G15: f | H15: S | I15: N/A | J15: N | K15: PARAMETROS | L15: LECTURAS | O15: COMENTARIOS
B16: ¿ El sistema se encontró en servicio ? | G16: M | H16: OK
B17: ¿ El stock de rociadores es el adecuado en cantidad y temperatura ? | G17: M | H17: OK | L17: 165ºf
B18: ¿ Se cuenta con las llaves adecuadas de los rociadores ? | G18: M | H18: OK
B19: Cantidad de rociadores instalados de acuerdo al diseño original. | G19: M | H19: OK | M19: 214
B20: ¿ No se han realizado modificaciones en el área protegida con relación al plano del diseño original ? | G20: M | H20: OK
B21: ¿ La válvula de control esta accesible ? | G21: M | H21: OK
B22: ¿ La válvula OS&Y opera al cerrarla y retorna a la posición de abierto ? | G22: M | H22: OK
B23: ¿ La válvula de control cierra y retorna a la posición de abierto ? | G23: M | H23: OK
B24: ¿ La válvula de control esta supervisada y/o asegurada ? | G24: M | H24: OK
B25: ¿ Operan los supervisores de válvula ? | G25: M | H25: OK
B26: ¿ Esta delimitada el área del riser del sistema ? | G26: M | H26: OK
B27: ¿ Las válvulas check mantienen la presión ? | G27: M | H27: OK
B28: ¿ La válvula de alarma esta en buen estado ? | G28: M | H28: OK
B29: ¿ La válvula de alarma mantiene la presión ? | G29: M | H29: OK
B30: Presión en la línea de alimentación | G30: M | H30: OK | K30: Psi | L30: 155
B31: ¿ La presión de alimentación es adecuada ? | G31: M | H31: OK
B32: Presión en la línea de rociadores | G32: M | H32: OK | K32: Psi | L32: 160
B33: ¿ La presión del sistema es adecuada ? | G33: M | H33: OK
B34: ¿ Coincide la lectura de los manómetros del riser con el manómetro certificado ? | G34: M | H34: OK
B35: ¿ La válvula de alivio opera adecuadamente ? | G35: M | H35: OK
B36: ¿ Las válvulas reguladora de presión esta abierta ? | G36: M | H36: OK
B37: ¿ Las válvulas reguladora de presión esta en buenas condiciones ? | G37: M | H37: OK
B38: ¿ Las válvulas reguladora de presión esta ajustada de acuerdo al criterio del diseño ? | G38: M | H38: OK | K38: Psi | M38: 175
B39: ¿ La válvula del drene opera adecuadamente ? | G39: M | H39: OK
B40: ¿ El detector de flujo y/o de Presión opera ? | G40: M | H40: OK
B41: ¿ La válvula de alivio del la línea de inspección opera ? | G41: M | H41: OK
B42: ¿ Las guardas de los rociadores son las aprobadas ? | G42: M | H42: OK | K42: UL o FM
B43: ¿ Los rociadores están libres de daños y fugas ? | G43: M | H43: OK
...

Sheet Sistema 3 
P1: FIRE CONTROL SYSTEMS
P2: Bucarest 12 Terranova Nogales, Sonora
P3: Tel. 104-1127 Cel. 631-357-941 las 24 Hrs.
P4: Patricia Campos Badillo
P5: RFC. CABP721117CW7
B6: REPORTE DE INSPECCION, PRUEBAS Y MANTENIMIENTO A SISTEMAS DE ROCIADORES | P6: E. Mail: firecontrolsystems@hotmail.com
B7: CLIENTE; | C7: Master Lock de Nogales Planta 2 | J7: CONTRATO : | L7: Mensual
B8: ATENCIÓN; | C8: Ing. Julio Landabazo | J8: INSPECTOR : | L8: ='Hidrantes Interiores'!S8 -> Santiago Campos
B9: SERVICIO: | C9: ='Tanque Agua'!C10 -> 7 de 12 | J9: FECHA : | L9: ='Sistema 1'!L9 -> 17 de Julio del 2025
C11: Sistema Nº 3
B13: f = FRECUENCIA M = MENSUAL Q = TRIMESTRAL A = ANUAL | G13: S: SATISFACTORIO N/A: NO APLICA N: NO SATISFACTORIO
B15: SISTEMAS HUMEDOS | G15: f | H15: S | I15: N/A | J15: N | K15: PARAMETROS | L15: LECTURAS | O15: COMENTARIOS
B16: ¿ El sistema se encontró en servicio ? | G16: M | H16: OK
B17: ¿ El stock de rociadores es el adecuado en cantidad y temperatura ? | G17: M | H17: OK | L17: 286ºF - K=11.2
B18: ¿ Se cuenta con las llaves adecuadas de los rociadores ? | G18: M | H18: OK
B19: Cantidad de rociadores instalados de acuerdo al diseño original. | G19: M | H19: OK | L19: 460
B20: ¿ No se han realizado modificaciones en el área protegida con relación al plano del diseño original ? | G20: M | H20: OK
B21: ¿ La válvula hacia los hidrantes esta abierta ? | G21: M | H21: OK
B22: ¿ La válvula hacia los hidrantes esta asegurada y/o supervisada ? | G22: M | H22: OK
B23: ¿ La válvula de control esta accesible ? | G23: M | H23: OK
B24: ¿ La válvula OS&Y opera al cerrarla y retorna a la posición de abierto ? | G24: M | H24: OK
B25: ¿ La válvula de control cierra y retorna a la posición de abierto ? | G25: M | H25: OK
B26: ¿ La válvula de control esta supervisada y/o asegurada ? | G26: M | H26: OK
B27: ¿ Operan los supervisores de válvula ? | G27: M | H27: OK
B28: ¿ Esta delimitada el área del riser del sistema ? | G28: M | H28: OK
B29: ¿ Las válvulas check mantienen la presión ? | G29: M | H29: OK
B30: ¿ La válvula de alarma esta en buen estado ? | G30: M | H30: OK
B31: ¿ La válvula de alarma mantiene la presión ? | G31: M | H31: OK
B32: Presión en la línea de alimentación | G32: M | H32: OK | K32: Psi | L32: 150
B33: ¿ La presión de alimentación es adecuada ? | G33: M | H33: OK
B34: Presión en la línea de rociadores | G34: M | H34: OK | K34: Psi | L34: 153
B35: ¿ La presión del sistema es adecuada ? | G35: M | H35: OK
B36: ¿ Coincide la lectura de los manómetros del riser con el manómetro certificado ? | G36: M | H36: OK
B37: ¿ La válvula de alivio opera adecuadamente ? | G37: M | H37: OK
B38: ¿ Las válvulas reguladora de presión esta abierta ? | G38: M | H38: OK
B39: ¿ Las válvulas reguladora de presión esta en buenas condiciones ? | G39: M | H39: OK
B40: ¿ Las válvulas reguladora de presión esta ajustada de acuerdo al criterio del diseño ? | G40: M | H40: OK
B41: ¿ La válvula del drene opera adecuadamente ? | G41: M | H41: OK
B42: ¿ El detector de flujo y/o de Presión opera ? | G42: M | H42: OK
B43: ¿ La válvula de alivio del la línea de inspección opera ? | G43: M | H43: OK
...

Sheet Sistema 3A 
P1: FIRE CONTROL SYSTEMS
P2: Bucarest 12 Terranova Nogales, Sonora
P3: Tel. 104-1127 Cel. 631-357-9141 las 24 Hrs.
P4: Patricia Campos Badillo
P5: RFC. CABP721117CW7
B6: REPORTE DE INSPECCION, PRUEBAS Y MANTENIMIENTO A SISTEMAS DE ROCIADORES | P6: E. Mail: firecontrolsystems@hotmail.com
B7: CLIENTE: | C7: Master Lock de Nogales Planta 2 | J7: CONTRATO : | L7: Mensual
B8: ATENCIÓN: | C8: Ing. Julio Landabazo | J8: INSPECTOR : | L8: ='Hidrantes Interiores'!S8 -> Santiago Campos
B9: SERVICIO: | C9: ='Tanque Agua'!C10 -> 7 de 12 | J9: FECHA : | L9: ='Sistema 1'!L9 -> 17 de Julio del 2025
C11: Sistema Nº 3A In Rack
B13: f = FRECUENCIA M = MENSUAL Q = TRIMESTRAL A = ANUAL | G13: S: SATISFACTORIO N/A: NO APLICA N: NO SATISFACTORIO
B15: SISTEMAS HUMEDOS | G15: f | H15: S | I15: N/A | J15: N | K15: PARAMETROS | L15: LECTURAS | O15: COMENTARIOS
B16: ¿ El sistema se encontró en servicio ? | G16: M | H16: OK
B17: ¿ El stock de rociadores es el adecuado en cantidad y temperatura ? | G17: M | H17: OK | L17: 165ºf
B18: ¿ Se cuenta con las llaves adecuadas de los rociadores ? | G18: M | H18: OK
B19: Cantidad de rociadores instalados de acuerdo al diseño original. | G19: M | H19: OK | M19: 238
B20: ¿ No se han realizado modificaciones en el área protegida con relación al plano del diseño original ? | G20: M | H20: OK
B21: ¿ La válvula de control esta accesible ? | G21: M | H21: OK
B22: ¿ La válvula OS&Y opera al cerrarla y retorna a la posición de abierto ? | G22: M | H22: OK
B23: ¿ La válvula de control cierra y retorna a la posición de abierto ? | G23: M | H23: OK
B24: ¿ La válvula de control esta supervisada y/o asegurada ? | G24: M | H24: OK
B25: ¿ Operan los supervisores de válvula ? | G25: M | H25: OK
B26: ¿ Esta delimitada el área del riser del sistema ? | G26: M | H26: OK
B27: ¿ Las válvulas check mantienen la presión ? | G27: M | H27: OK
B28: ¿ La válvula de alarma esta en buen estado ? | G28: M | H28: OK
B29: ¿ La válvula de alarma mantiene la presión ? | G29: M | H29: OK
B30: Presión en la línea de alimentación | G30: M | J30: X | K30: Psi | L30: xxx | O30: Descalibrado
B31: ¿ La presión de alimentación es adecuada ? | G31: M | H31: OK
B32: Presión en la línea de rociadores | G32: M | H32: OK | K32: Psi | L32: 155
B33: ¿ La presión del sistema es adecuada ? | G33: M | H33: OK
B34: ¿ Coincide la lectura de los manómetros del riser con el manómetro certificado ? | G34: M | H34: OK
B35: ¿ La válvula de alivio opera adecuadamente ? | G35: M | H35: OK
B36: ¿ Las válvulas reguladora de presión esta abierta ? | G36: M | H36: OK
B37: ¿ Las válvulas reguladora de presión esta en buenas condiciones ? | G37: M | H37: OK
B38: ¿ Las válvulas reguladora de presión esta ajustada de acuerdo al criterio del diseño ? | G38: M | H38: OK | K38: Psi | M38: 175
B39: ¿ La válvula del drene opera adecuadamente ? | G39: M | H39: OK
B40: ¿ El detector de flujo y/o de Presión opera ? | G40: M | H40: OK
B41: ¿ La válvula de alivio del la línea de inspección opera ? | G41: M | H41: OK
B42: ¿ Las guardas de los rociadores son las aprobadas ? | G42: M | H42: OK | K42: UL o FM
B43: ¿ Los rociadores están libres de daños y fugas ? | G43: M | H43: OK
...

Sheet Sistema 4
P1: FIRE CONTROL SYSTEMS
P2: Bucarest 12 Terranova Nogales, Sonora
P3: Tel. 104-1127 Cel. 631-357-9141 las 24 Hrs.
P4: Patricia Campos Badillo
P5: RFC. CABP721117CW7
B6: REPORTE DE INSPECCION, PRUEBAS Y MANTENIMIENTO A SISTEMAS DE ROCIADORES | P6: E. Mail: firecontrolsystems@hotmail.com
B7: CLIENTE: | C7: Master Lock de Nogales Planta 2 | J7: CONTRATO : | L7: Mensual
B8: ATENCION: | C8: Ing. Julio Landabazo | J8: INSPECTOR : | L8: ='Hidrantes Interiores'!S8 -> Santiago Campos
B9: SERVICIO: | C9: ='Tanque Agua'!C10 -> 7 de 12 | J9: FECHA : | L9: ='Sistema 1'!L9 -> 17 de Julio del 2025
C11: Sistema Nº 4
B13: f = FRECUENCIA M = MENSUAL Q = TRIMESTRAL A = ANUAL | G13: S: SATISFACTORIO N/A: NO APLICA N: NO SATISFACTORIO
B15: SISTEMAS HUMEDOS | G15: f | H15: S | I15: N/A | J15: N | K15: PARAMETROS | L15: LECTURAS | O15: COMENTARIOS
B16: ¿ El sistema se encontró en servicio ? | G16: M | H16: OK
B17: ¿ El stock de rociadores es el adecuado en cantidad y temperatura ? | G17: M | H17: OK | L17: 286ºF - K=11.2
B18: ¿ Se cuenta con las llaves adecuadas de los rociadores ? | G18: M | H18: OK
B19: Cantidad de rociadores instalados de acuerdo al diseño original. | G19: M | H19: OK | L19: 584
B20: ¿ No se han realizado modificaciones en el área protegida con relación al plano del diseño original ? | G20: M | H20: OK
B21: ¿ La válvula hacia los hidrantes esta abierta ? | G21: M | H21: OK
B22: ¿ La válvula hacia los hidrantes esta asegurada y/o supervisada ? | G22: M | H22: OK
B23: ¿ La válvula de control esta accesible ? | G23: M | H23: OK
B24: ¿ La válvula OS&Y opera al cerrarla y retorna a la posición de abierto ? | G24: M | H24: OK
B25: ¿ La válvula de control cierra y retorna a la posición de abierto ? | G25: M | H25: OK
B26: ¿ La válvula de control esta supervisada y/o asegurada ? | G26: M | H26: OK
B27: ¿ Operan los supervisores de válvula ? | G27: M | H27: OK
B28: ¿ Esta delimitada el área del riser del sistema ? | G28: M | H28: OK
B29: ¿ Las válvulas check mantienen la presión ? | G29: M | H29: OK
B30: ¿ La válvula de alarma esta en buen estado ? | G30: M | H30: OK
B31: ¿ La válvula de alarma mantiene la presión ? | G31: M | H31: OK
B32: Presión en la línea de alimentación | G32: M | H32: OK | K32: Psi | L32: 150
B33: ¿ La presión de alimentación es adecuada ? | G33: M | H33: OK
B34: Presión en la línea de rociadores | G34: M | H34: OK | K34: Psi | L34: 160
B35: ¿ La presión del sistema es adecuada ? | G35: M | H35: OK
B36: ¿ Coincide la lectura de los manómetros del riser con el manómetro certificado ? | G36: M | H36: OK
B37: ¿ La válvula de alivio opera adecuadamente ? | G37: M | H37: OK
B38: ¿ Las válvulas reguladora de presión esta abierta ? | G38: M | H38: OK
B39: ¿ Las válvulas reguladora de presión esta en buenas condiciones ? | G39: M | H39: OK
B40: ¿ Las válvulas reguladora de presión esta ajustada de acuerdo al criterio del diseño ? | G40: M | H40: OK | K40: Psi | M40: 175
B41: ¿ La válvula del drene opera adecuadamente ? | G41: M | H41: OK
B42: ¿ El detector de flujo y/o de Presión opera ? | G42: M | H42: OK
B43: ¿ La válvula de alimentación del anticongelante esta abierta ? | G43: M | H43: OK
...

Sheet Sistema 5
P1: FIRE CONTROL SYSTEMS
P2: Bucarest 12 Terranova Nogales, Sonora
P3: Tel. 104-1127 Cel. 631-357-9141 las 24 Hrs.
P4: Patricia Campos Badillo
P5: RFC. CABP721117CW7
B6: REPORTE DE INSPECCION, PRUEBAS Y MANTENIMIENTO A SISTEMAS DE ROCIADORES | P6: E. Mail: firecontrolsystems@hotmail.com
B7: CLIENTE: | C7: Master Lock de Nogales Planta 2 | J7: CONTRATO : | L7: Mensual
B8: ATENCIÓN: | C8: Ing. Julio Landabazo | J8: INSPECTOR : | L8: ='Hidrantes Interiores'!S8 -> Santiago Campos
B9: SERVICIO: | C9: ='Tanque Agua'!C10 -> 7 de 12 | J9: FECHA : | L9: ='Sistema 1'!L9 -> 17 de Julio del 2025
C11: Sistema Nº 5
B13: f = FRECUENCIA M = MENSUAL Q = TRIMESTRAL A = ANUAL | G13: S: SATISFACTORIO N/A: NO APLICA N: NO SATISFACTORIO
B15: SISTEMAS HUMEDOS | G15: f | H15: S | I15: N/A | J15: N | K15: PARAMETROS | L15: LECTURAS | O15: COMENTARIOS
B16: ¿ El sistema se encontró en servicio ? | G16: M | H16: OK
B17: ¿ El stock de rociadores es el adecuado en cantidad y temperatura ? | G17: M | H17: OK | L17: 286ºF - K=11.2
B18: ¿ Se cuenta con las llaves adecuadas de los rociadores ? | G18: M | H18: OK
B19: Cantidad de rociadores instalados de acuerdo al diseño original. | G19: M | H19: OK
B20: ¿ No se han realizado modificaciones en el área protegida con relación al plano del diseño original ? | G20: M | H20: OK
B21: ¿ La válvula hacia los hidrantes esta abierta ? | G21: M | H21: OK
B22: ¿ La válvula hacia los hidrantes esta asegurada y/o supervisada ? | G22: M | H22: OK
B23: ¿ La válvula de control esta accesible ? | G23: M | H23: OK
B24: ¿ La válvula OS&Y opera al cerrarla y retorna a la posición de abierto ? | G24: M | H24: OK
B25: ¿ La válvula de control cierra y retorna a la posición de abierto ? | G25: M | H25: OK
B26: ¿ La válvula de control esta supervisada y/o asegurada ? | G26: M | H26: OK
B27: ¿ Operan los supervisores de válvula ? | G27: M | H27: OK
